2020-12-10 14:09:35 INFO (MainThread) [homeassistant.setup] Setup of domain logger took 0.0 seconds
2020-12-10 14:09:36 INFO (MainThread) [homeassistant.setup] Setting up recorder
2020-12-10 14:09:36 INFO (MainThread) [homeassistant.setup] Setting up http
2020-12-10 14:09:36 INFO (MainThread) [homeassistant.setup] Setup of domain http took 0.0 seconds
2020-12-10 14:09:36 INFO (MainThread) [homeassistant.setup] Setting up system_log
2020-12-10 14:09:36 INFO (MainThread) [homeassistant.setup] Setup of domain system_log took 0.0 seconds
2020-12-10 14:09:46 WARNING (MainThread) [homeassistant.setup] Setup of recorder is taking over 10 seconds.
2020-12-10 14:10:35 WARNING (MainThread) [homeassistant.bootstrap] Waiting on integrations to complete setup: recorder
2020-12-10 14:10:40 WARNING (Recorder) [homeassistant.components.recorder] Ended unfinished session (id=11 from 2020-12-10 13:14:34.736813)
2020-12-10 14:10:40 INFO (MainThread) [homeassistant.setup] Setup of domain recorder took 63.8 seconds
2020-12-10 14:10:40 INFO (MainThread) [homeassistant.bootstrap] Setting up stage 1: {'cloud', 'alexa', 'lovelace', 'device_automation', 'onboarding', 'config', 'frontend', 'webhook', 'api', 'http', 'auth', 'websocket_api', 'system_log', 'person', 'image', 'search'}
2020-12-10 14:10:41 INFO (MainThread) [homeassistant.setup] Setting up alexa
2020-12-10 14:10:41 INFO (MainThread) [homeassistant.setup] Setup of domain alexa took 0.0 seconds
2020-12-10 14:10:41 INFO (MainThread) [homeassistant.setup] Setting up lovelace
2020-12-10 14:10:41 INFO (MainThread) [homeassistant.setup] Setting up device_automation
2020-12-10 14:10:41 INFO (MainThread) [homeassistant.setup] Setup of domain device_automation took 0.0 seconds
2020-12-10 14:10:41 INFO (MainThread) [homeassistant.setup] Setting up config
2020-12-10 14:10:41 INFO (MainThread) [homeassistant.setup] Setting up webhook
2020-12-10 14:10:41 INFO (MainThread) [homeassistant.setup] Setup of domain webhook took 0.0 seconds
2020-12-10 14:10:41 INFO (MainThread) [homeassistant.setup] Setting up api
2020-12-10 14:10:41 INFO (MainThread) [homeassistant.setup] Setting up auth
2020-12-10 14:10:41 INFO (MainThread) [homeassistant.setup] Setup of domain auth took 0.0 seconds
2020-12-10 14:10:41 INFO (MainThread) [homeassistant.setup] Setting up websocket_api
2020-12-10 14:10:41 INFO (MainThread) [homeassistant.setup] Setup of domain websocket_api took 0.0 seconds
2020-12-10 14:10:41 INFO (MainThread) [homeassistant.setup] Setup of domain api took 0.2 seconds
2020-12-10 14:10:41 INFO (MainThread) [homeassistant.setup] Setup of domain config took 0.2 seconds
2020-12-10 14:10:41 INFO (MainThread) [homeassistant.setup] Setting up image
2020-12-10 14:10:41 INFO (MainThread) [homeassistant.setup] Setting up search
2020-12-10 14:10:41 INFO (MainThread) [homeassistant.setup] Setup of domain search took 0.0 seconds
2020-12-10 14:10:41 INFO (MainThread) [homeassistant.setup] Setup of domain lovelace took 0.3 seconds
2020-12-10 14:10:41 INFO (MainThread) [homeassistant.setup] Setup of domain image took 0.0 seconds
2020-12-10 14:10:41 INFO (SyncWorker_3) [homeassistant.loader] Loaded camera from homeassistant.components.camera
2020-12-10 14:10:41 INFO (SyncWorker_2) [homeassistant.loader] Loaded google_assistant from homeassistant.components.google_assistant
2020-12-10 14:10:41 INFO (MainThread) [homeassistant.setup] Setting up person
2020-12-10 14:10:41 INFO (SyncWorker_1) [homeassistant.loader] Loaded media_player from homeassistant.components.media_player
2020-12-10 14:10:43 INFO (MainThread) [homeassistant.setup] Setting up cloud
2020-12-10 14:10:43 INFO (MainThread) [homeassistant.setup] Setup of domain cloud took 0.1 seconds
2020-12-10 14:10:43 INFO (MainThread) [homeassistant.setup] Setup of domain person took 2.3 seconds
2020-12-10 14:10:43 INFO (MainThread) [homeassistant.setup] Setting up onboarding
2020-12-10 14:10:43 INFO (MainThread) [homeassistant.setup] Setup of domain onboarding took 0.0 seconds
2020-12-10 14:10:43 INFO (SyncWorker_3) [homeassistant.loader] Loaded device_tracker from homeassistant.components.device_tracker
2020-12-10 14:10:43 INFO (SyncWorker_0) [homeassistant.loader] Loaded hassio from homeassistant.components.hassio
2020-12-10 14:10:43 INFO (SyncWorker_2) [homeassistant.loader] Loaded panel_custom from homeassistant.components.panel_custom
2020-12-10 14:10:43 INFO (MainThread) [homeassistant.setup] Setting up frontend
2020-12-10 14:10:43 INFO (MainThread) [homeassistant.setup] Setup of domain frontend took 0.0 seconds
2020-12-10 14:10:43 INFO (MainThread) [homeassistant.bootstrap] Setting up stage 2: {'input_text', 'media_source', 'input_boolean', 'zone', 'input_number', 'cast', 'ssdp', 'upnp', 'map', 'scene', 'tag', 'influxdb', 'blueprint', 'lifx', 'sun', 'tts', 'updater', 'script', 'zeroconf', 'speedtestdotnet', 'system_health', 'logbook', 'counter', 'group', 'timer', 'input_select', 'automation', 'history', 'mobile_app', 'input_datetime', 'default_config', 'smartthings', 'sensor', 'hue'}
2020-12-10 14:10:43 INFO (MainThread) [homeassistant.setup] Setting up input_text
2020-12-10 14:10:43 INFO (MainThread) [homeassistant.setup] Setting up media_source
2020-12-10 14:10:43 INFO (MainThread) [homeassistant.setup] Setting up input_boolean
2020-12-10 14:10:43 INFO (MainThread) [homeassistant.setup] Setting up zone
2020-12-10 14:10:43 INFO (MainThread) [homeassistant.setup] Setting up input_number
2020-12-10 14:10:43 INFO (MainThread) [homeassistant.setup] Setting up map
2020-12-10 14:10:43 INFO (MainThread) [homeassistant.setup] Setup of domain map took 0.0 seconds
2020-12-10 14:10:43 INFO (MainThread) [homeassistant.setup] Setting up scene
2020-12-10 14:10:43 INFO (MainThread) [homeassistant.components.scene] Setting up scene.homeassistant
2020-12-10 14:10:43 INFO (MainThread) [homeassistant.setup] Setting up tag
2020-12-10 14:10:44 INFO (MainThread) [homeassistant.setup] Setting up influxdb
2020-12-10 14:10:44 INFO (MainThread) [homeassistant.setup] Setting up blueprint
2020-12-10 14:10:44 INFO (MainThread) [homeassistant.setup] Setup of domain blueprint took 0.0 seconds
2020-12-10 14:10:44 INFO (MainThread) [homeassistant.setup] Setting up sun
2020-12-10 14:10:44 INFO (MainThread) [homeassistant.setup] Setup of domain sun took 0.1 seconds
2020-12-10 14:10:45 INFO (MainThread) [homeassistant.setup] Setting up updater
2020-12-10 14:10:45 INFO (MainThread) [homeassistant.setup] Setup of domain updater took 0.0 seconds
2020-12-10 14:10:45 INFO (MainThread) [homeassistant.setup] Setting up script
2020-12-10 14:10:45 INFO (MainThread) [homeassistant.setup] Setup of domain script took 0.0 seconds
2020-12-10 14:10:45 INFO (MainThread) [homeassistant.setup] Setting up speedtestdotnet
2020-12-10 14:10:45 INFO (MainThread) [homeassistant.setup] Setup of domain speedtestdotnet took 0.0 seconds
2020-12-10 14:10:45 INFO (MainThread) [homeassistant.setup] Setting up system_health
2020-12-10 14:10:45 INFO (MainThread) [homeassistant.setup] Setting up logbook
2020-12-10 14:10:45 INFO (MainThread) [homeassistant.setup] Setting up counter
2020-12-10 14:10:45 INFO (MainThread) [homeassistant.setup] Setting up group
2020-12-10 14:10:45 INFO (MainThread) [homeassistant.setup] Setting up timer
2020-12-10 14:10:45 INFO (MainThread) [homeassistant.setup] Setting up input_select
2020-12-10 14:10:45 INFO (MainThread) [homeassistant.setup] Setting up history
2020-12-10 14:10:45 INFO (MainThread) [homeassistant.setup] Setup of domain history took 0.0 seconds
2020-12-10 14:10:45 INFO (MainThread) [homeassistant.setup] Setting up input_datetime
2020-12-10 14:10:45 INFO (SyncWorker_3) [homeassistant.loader] Loaded darksky from homeassistant.components.darksky
2020-12-10 14:10:45 INFO (SyncWorker_3) [homeassistant.loader] Loaded binary_sensor from homeassistant.components.binary_sensor
2020-12-10 14:10:45 INFO (MainThread) [homeassistant.setup] Setting up sensor
2020-12-10 14:10:45 INFO (MainThread) [homeassistant.setup] Setup of domain sensor took 0.0 seconds
2020-12-10 14:10:45 INFO (MainThread) [homeassistant.setup] Setup of domain media_source took 1.6 seconds
2020-12-10 14:10:45 INFO (MainThread) [homeassistant.setup] Setup of domain scene took 1.6 seconds
2020-12-10 14:10:45 INFO (SyncWorker_5) [homeassistant.loader] Loaded google_translate from homeassistant.components.google_translate
2020-12-10 14:10:45 INFO (MainThread) [homeassistant.setup] Setting up zeroconf
2020-12-10 14:10:45 INFO (MainThread) [homeassistant.setup] Setup of domain system_health took 0.8 seconds
2020-12-10 14:10:45 INFO (MainThread) [homeassistant.setup] Setup of domain logbook took 0.8 seconds
2020-12-10 14:10:45 INFO (MainThread) [homeassistant.setup] Setup of domain group took 0.8 seconds
2020-12-10 14:10:45 INFO (MainThread) [homeassistant.setup] Setting up automation
2020-12-10 14:10:45 INFO (MainThread) [homeassistant.setup] Setup of domain automation took 0.0 seconds
2020-12-10 14:10:46 INFO (MainThread) [homeassistant.setup] Setting up smartthings
2020-12-10 14:10:46 INFO (MainThread) [homeassistant.components.sensor] Setting up sensor.darksky
2020-12-10 14:10:46 INFO (MainThread) [homeassistant.setup] Setup of domain input_text took 3.1 seconds
2020-12-10 14:10:46 INFO (MainThread) [homeassistant.setup] Setup of domain input_boolean took 3.1 seconds
2020-12-10 14:10:47 INFO (MainThread) [homeassistant.setup] Setup of domain input_number took 3.3 seconds
2020-12-10 14:10:47 INFO (MainThread) [homeassistant.setup] Setting up binary_sensor
2020-12-10 14:10:47 INFO (MainThread) [homeassistant.setup] Setup of domain binary_sensor took 0.0 seconds
2020-12-10 14:10:47 INFO (MainThread) [homeassistant.setup] Setup of domain tag took 3.3 seconds
2020-12-10 14:10:47 INFO (MainThread) [homeassistant.setup] Setup of domain counter took 2.1 seconds
2020-12-10 14:10:47 INFO (MainThread) [homeassistant.setup] Setup of domain influxdb took 2.4 seconds
2020-12-10 14:10:47 INFO (MainThread) [homeassistant.setup] Setup of domain timer took 2.1 seconds
2020-12-10 14:10:47 INFO (MainThread) [homeassistant.setup] Setup of domain input_select took 2.1 seconds
2020-12-10 14:10:47 INFO (MainThread) [homeassistant.setup] Setup of domain input_datetime took 2.1 seconds
2020-12-10 14:10:47 INFO (MainThread) [homeassistant.setup] Setting up tts
2020-12-10 14:10:47 INFO (MainThread) [homeassistant.setup] Setup of domain zeroconf took 1.4 seconds
2020-12-10 14:10:47 INFO (MainThread) [homeassistant.setup] Setting up lifx
2020-12-10 14:10:47 INFO (MainThread) [homeassistant.setup] Setup of domain lifx took 0.0 seconds
2020-12-10 14:10:47 INFO (MainThread) [homeassistant.setup] Setup of domain zone took 3.4 seconds
2020-12-10 14:10:47 INFO (MainThread) [homeassistant.setup] Setup of domain smartthings took 0.4 seconds
2020-12-10 14:10:47 INFO (MainThread) [homeassistant.components.binary_sensor] Setting up binary_sensor.updater
2020-12-10 14:10:47 INFO (MainThread) [homeassistant.setup] Setting up upnp
2020-12-10 14:10:47 INFO (MainThread) [homeassistant.setup] Setting up hue
2020-12-10 14:10:47 INFO (MainThread) [homeassistant.setup] Setup of domain hue took 0.0 seconds
2020-12-10 14:10:47 INFO (MainThread) [homeassistant.setup] Setup of domain upnp took 0.2 seconds
2020-12-10 14:10:47 INFO (SyncWorker_1) [homeassistant.loader] Loaded notify from homeassistant.components.notify
2020-12-10 14:10:47 INFO (SyncWorker_3) [homeassistant.loader] Loaded light from homeassistant.components.light
2020-12-10 14:10:47 INFO (MainThread) [homeassistant.setup] Setting up ssdp
2020-12-10 14:10:47 INFO (MainThread) [homeassistant.setup] Setup of domain ssdp took 0.0 seconds
2020-12-10 14:10:47 INFO (MainThread) [homeassistant.setup] Setup of domain tts took 0.5 seconds
2020-12-10 14:10:47 INFO (MainThread) [homeassistant.setup] Setting up light
2020-12-10 14:10:47 INFO (MainThread) [homeassistant.setup] Setting up mobile_app
2020-12-10 14:10:47 INFO (MainThread) [homeassistant.setup] Setup of domain light took 0.2 seconds
2020-12-10 14:10:48 INFO (MainThread) [homeassistant.components.light] Setting up light.lifx
2020-12-10 14:10:48 INFO (MainThread) [homeassistant.setup] Setup of domain mobile_app took 0.1 seconds
2020-12-10 14:10:48 INFO (SyncWorker_2) [homeassistant.loader] Loaded plex from homeassistant.components.plex
2020-12-10 14:10:48 INFO (MainThread) [homeassistant.setup] Setting up notify
2020-12-10 14:10:48 INFO (MainThread) [homeassistant.setup] Setup of domain notify took 0.0 seconds
2020-12-10 14:10:48 INFO (MainThread) [homeassistant.components.sensor] Setting up sensor.speedtestdotnet
2020-12-10 14:10:48 INFO (SyncWorker_0) [homeassistant.loader] Loaded sonos from homeassistant.components.sonos
2020-12-10 14:10:48 INFO (MainThread) [homeassistant.setup] Setting up device_tracker
2020-12-10 14:10:48 INFO (MainThread) [homeassistant.components.sensor] Setting up sensor.mobile_app
2020-12-10 14:10:48 INFO (MainThread) [homeassistant.components.binary_sensor] Setting up binary_sensor.mobile_app
2020-12-10 14:10:48 INFO (MainThread) [homeassistant.components.notify] Setting up notify.mobile_app
2020-12-10 14:10:48 INFO (MainThread) [homeassistant.setup] Setup of domain device_tracker took 0.1 seconds
2020-12-10 14:10:48 INFO (MainThread) [homeassistant.setup] Setting up default_config
2020-12-10 14:10:48 INFO (MainThread) [homeassistant.setup] Setup of domain default_config took 0.0 seconds
2020-12-10 14:10:48 INFO (MainThread) [homeassistant.components.device_tracker] Setting up device_tracker.mobile_app
2020-12-10 14:10:48 INFO (MainThread) [homeassistant.components.light] Setting up light.hue
2020-12-10 14:10:48 INFO (MainThread) [homeassistant.components.binary_sensor] Setting up binary_sensor.hue
2020-12-10 14:10:48 INFO (MainThread) [homeassistant.components.sensor] Setting up sensor.hue
2020-12-10 14:10:48 INFO (MainThread) [homeassistant.components.updater] Submitted analytics to Home Assistant servers. Information submitted includes {}
2020-12-10 14:10:48 INFO (MainThread) [homeassistant.setup] Setting up cast
2020-12-10 14:10:48 INFO (MainThread) [homeassistant.setup] Setup of domain cast took 0.0 seconds
2020-12-10 14:10:48 INFO (MainThread) [homeassistant.setup] Setting up media_player
2020-12-10 14:10:48 INFO (MainThread) [homeassistant.setup] Setup of domain media_player took 0.0 seconds
2020-12-10 14:10:48 INFO (MainThread) [homeassistant.components.media_player] Setting up media_player.cast
2020-12-10 14:10:48 WARNING (Thread-5) [zeroconf] Error sending through socket 11
Traceback (most recent call last):
  File "/srv/homeassistant/lib/python3.8/site-packages/zeroconf/__init__.py", line 2914, in send
    bytes_sent = s.sendto(packet, 0, (real_addr, port))
OSError: [Errno 126] Required key not available
2020-12-10 14:10:48 INFO (SyncWorker_2) [pychromecast] Querying device status
2020-12-10 14:10:48 INFO (SyncWorker_4) [pychromecast] Querying device status
2020-12-10 14:10:49 INFO (SyncWorker_5) [homeassistant.loader] Loaded climate from homeassistant.components.climate
2020-12-10 14:10:49 INFO (SyncWorker_3) [homeassistant.loader] Loaded lock from homeassistant.components.lock
2020-12-10 14:10:49 INFO (SyncWorker_2) [homeassistant.loader] Loaded switch from homeassistant.components.switch
2020-12-10 14:10:49 INFO (SyncWorker_0) [homeassistant.loader] Loaded fan from homeassistant.components.fan
2020-12-10 14:10:49 INFO (SyncWorker_1) [homeassistant.loader] Loaded cover from homeassistant.components.cover
2020-12-10 14:10:49 INFO (MainThread) [homeassistant.components.light] Setting up light.smartthings
2020-12-10 14:10:49 INFO (MainThread) [homeassistant.components.binary_sensor] Setting up binary_sensor.smartthings
2020-12-10 14:10:49 INFO (MainThread) [homeassistant.components.sensor] Setting up sensor.smartthings
2020-12-10 14:10:49 INFO (MainThread) [homeassistant.components.scene] Setting up scene.smartthings
2020-12-10 14:10:49 INFO (MainThread) [homeassistant.setup] Setting up climate
2020-12-10 14:10:49 INFO (MainThread) [homeassistant.setup] Setup of domain climate took 0.0 seconds
2020-12-10 14:10:49 INFO (MainThread) [homeassistant.setup] Setting up lock
2020-12-10 14:10:49 INFO (MainThread) [homeassistant.setup] Setup of domain lock took 0.0 seconds
2020-12-10 14:10:49 INFO (MainThread) [homeassistant.setup] Setting up switch
2020-12-10 14:10:49 INFO (MainThread) [homeassistant.setup] Setup of domain switch took 0.0 seconds
2020-12-10 14:10:49 INFO (MainThread) [homeassistant.setup] Setting up fan
2020-12-10 14:10:49 INFO (MainThread) [homeassistant.setup] Setup of domain fan took 0.0 seconds
2020-12-10 14:10:49 INFO (MainThread) [homeassistant.setup] Setting up cover
2020-12-10 14:10:49 INFO (MainThread) [homeassistant.setup] Setup of domain cover took 0.0 seconds
2020-12-10 14:10:49 INFO (MainThread) [homeassistant.components.climate] Setting up climate.smartthings
2020-12-10 14:10:49 INFO (MainThread) [homeassistant.components.lock] Setting up lock.smartthings
2020-12-10 14:10:49 INFO (MainThread) [homeassistant.components.switch] Setting up switch.smartthings
2020-12-10 14:10:49 INFO (MainThread) [homeassistant.components.fan] Setting up fan.smartthings
2020-12-10 14:10:49 INFO (MainThread) [homeassistant.components.cover] Setting up cover.smartthings
2020-12-10 14:10:57 INFO (MainThread) [homeassistant.components.sensor] Setting up sensor.upnp
2020-12-10 14:10:58 INFO (MainThread) [homeassistant.bootstrap] Home Assistant initialized in 83.28s
2020-12-10 14:10:58 INFO (MainThread) [homeassistant.core] Starting Home Assistant
2020-12-10 14:10:58 INFO (MainThread) [homeassistant.core] Timer:starting
2020-12-10 14:10:58 INFO (SyncWorker_0) [homeassistant.components.zeroconf] Starting Zeroconf broadcast
2020-12-10 14:10:58 INFO (SyncWorker_3) [homeassistant.loader] Loaded homekit_controller from homeassistant.components.homekit_controller
2020-12-10 14:26:56 ERROR (influxdb) [homeassistant.components.influxdb] Cannot connect to InfluxDB due to 'HTTPConnectionPool(host='192.168.1.4', port=8086): Read timed out. (read timeout=5)'. Please check that the provided connection details (host, port, etc.) are correct and that your InfluxDB server is running and accessible.
2020-12-10 14:27:04 ERROR (influxdb) [homeassistant.components.influxdb] Resumed, lost 1 events.
2020-12-10 14:27:49 ERROR (influxdb) [homeassistant.components.influxdb] Cannot connect to InfluxDB due to 'HTTPConnectionPool(host='192.168.1.4', port=8086): Read timed out. (read timeout=5)'. Please check that the provided connection details (host, port, etc.) are correct and that your InfluxDB server is running and accessible.
2020-12-10 14:28:01 ERROR (influxdb) [homeassistant.components.influxdb] Resumed, lost 1 events.
2020-12-10 14:29:16 ERROR (influxdb) [homeassistant.components.influxdb] Cannot connect to InfluxDB due to 'HTTPConnectionPool(host='192.168.1.4', port=8086): Read timed out. (read timeout=5)'. Please check that the provided connection details (host, port, etc.) are correct and that your InfluxDB server is running and accessible.
2020-12-10 14:29:23 ERROR (influxdb) [homeassistant.components.influxdb] Resumed, lost 1 events.
2020-12-10 14:30:30 ERROR (influxdb) [homeassistant.components.influxdb] Cannot connect to InfluxDB due to 'HTTPConnectionPool(host='192.168.1.4', port=8086): Read timed out. (read timeout=5)'. Please check that the provided connection details (host, port, etc.) are correct and that your InfluxDB server is running and accessible.
2020-12-10 14:30:36 ERROR (influxdb) [homeassistant.components.influxdb] Resumed, lost 1 events.
2020-12-10 14:31:19 ERROR (influxdb) [homeassistant.components.influxdb] Cannot connect to InfluxDB due to 'HTTPConnectionPool(host='192.168.1.4', port=8086): Read timed out. (read timeout=5)'. Please check that the provided connection details (host, port, etc.) are correct and that your InfluxDB server is running and accessible.
2020-12-10 14:31:23 ERROR (influxdb) [homeassistant.components.influxdb] Resumed, lost 2 events.
2020-12-10 14:34:11 ERROR (influxdb) [homeassistant.components.influxdb] Cannot connect to InfluxDB due to 'HTTPConnectionPool(host='192.168.1.4', port=8086): Read timed out. (read timeout=5)'. Please check that the provided connection details (host, port, etc.) are correct and that your InfluxDB server is running and accessible.
2020-12-10 14:34:13 ERROR (influxdb) [homeassistant.components.influxdb] Resumed, lost 1 events.
2020-12-10 14:34:48 ERROR (influxdb) [homeassistant.components.influxdb] Cannot connect to InfluxDB due to 'HTTPConnectionPool(host='192.168.1.4', port=8086): Read timed out. (read timeout=5)'. Please check that the provided connection details (host, port, etc.) are correct and that your InfluxDB server is running and accessible.
2020-12-10 14:34:50 ERROR (influxdb) [homeassistant.components.influxdb] Resumed, lost 1 events.
2020-12-10 14:35:27 ERROR (influxdb) [homeassistant.components.influxdb] Cannot connect to InfluxDB due to 'HTTPConnectionPool(host='192.168.1.4', port=8086): Read timed out. (read timeout=5)'. Please check that the provided connection details (host, port, etc.) are correct and that your InfluxDB server is running and accessible.
2020-12-10 14:35:39 ERROR (influxdb) [homeassistant.components.influxdb] Resumed, lost 1 events.
2020-12-10 14:36:14 ERROR (influxdb) [homeassistant.components.influxdb] Cannot connect to InfluxDB due to 'HTTPConnectionPool(host='192.168.1.4', port=8086): Read timed out. (read timeout=5)'. Please check that the provided connection details (host, port, etc.) are correct and that your InfluxDB server is running and accessible.
2020-12-10 14:36:20 ERROR (influxdb) [homeassistant.components.influxdb] Resumed, lost 9 events.
2020-12-10 14:37:08 ERROR (influxdb) [homeassistant.components.influxdb] Cannot connect to InfluxDB due to 'HTTPConnectionPool(host='192.168.1.4', port=8086): Read timed out. (read timeout=5)'. Please check that the provided connection details (host, port, etc.) are correct and that your InfluxDB server is running and accessible.
2020-12-10 14:37:12 ERROR (influxdb) [homeassistant.components.influxdb] Resumed, lost 3 events.
2020-12-10 14:43:48 ERROR (influxdb) [homeassistant.components.influxdb] Cannot connect to InfluxDB due to 'HTTPConnectionPool(host='192.168.1.4', port=8086): Read timed out. (read timeout=5)'. Please check that the provided connection details (host, port, etc.) are correct and that your InfluxDB server is running and accessible.
2020-12-10 14:43:51 ERROR (influxdb) [homeassistant.components.influxdb] Resumed, lost 1 events.
2020-12-10 14:44:31 ERROR (influxdb) [homeassistant.components.influxdb] Cannot connect to InfluxDB due to 'HTTPConnectionPool(host='192.168.1.4', port=8086): Read timed out. (read timeout=5)'. Please check that the provided connection details (host, port, etc.) are correct and that your InfluxDB server is running and accessible.
2020-12-10 14:44:38 ERROR (influxdb) [homeassistant.components.influxdb] Resumed, lost 1 events.
2020-12-10 14:46:01 ERROR (influxdb) [homeassistant.components.influxdb] Cannot connect to InfluxDB due to 'HTTPConnectionPool(host='192.168.1.4', port=8086): Read timed out. (read timeout=5)'. Please check that the provided connection details (host, port, etc.) are correct and that your InfluxDB server is running and accessible.
2020-12-10 14:46:08 ERROR (influxdb) [homeassistant.components.influxdb] Resumed, lost 1 events.
2020-12-10 14:55:03 ERROR (influxdb) [homeassistant.components.influxdb] Cannot connect to InfluxDB due to 'b'{"error":"write failed"}\n''. Please check that the provided connection details (host, port, etc.) are correct and that your InfluxDB server is running and accessible.
2020-12-10 14:56:16 ERROR (influxdb) [homeassistant.components.influxdb] Resumed, lost 92 events.
2020-12-10 21:19:58 ERROR (MainThread) [homeassistant.components.upnp] Unexpected error fetching Home Hub 3000 Internet Gateway Device data: Error during async_call(), status: 403, body: <html><body><h1>403 Forbidden</h1></body></html>
Traceback (most recent call last):
  File "/srv/homeassistant/lib/python3.8/site-packages/homeassistant/helpers/update_coordinator.py", line 144, in async_refresh
    self.data = await self._async_update_data()
  File "/srv/homeassistant/lib/python3.8/site-packages/homeassistant/helpers/update_coordinator.py", line 132, in _async_update_data
    return await self.update_method()
  File "/srv/homeassistant/lib/python3.8/site-packages/homeassistant/components/upnp/device.py", line 128, in async_get_traffic_data
    values = await asyncio.gather(
  File "/srv/homeassistant/lib/python3.8/site-packages/async_upnp_client/profiles/igd.py", line 120, in async_get_total_packets_sent
    result = await action.async_call()
  File "/srv/homeassistant/lib/python3.8/site-packages/async_upnp_client/client.py", line 519, in async_call
    raise UpnpError('Error during async_call(), status: %s, body: %s' %
async_upnp_client.client.UpnpError: Error during async_call(), status: 403, body: <html><body><h1>403 Forbidden</h1></body></html>
2020-12-10 21:20:28 INFO (MainThread) [homeassistant.components.upnp] Fetching Home Hub 3000 Internet Gateway Device data recovered
2020-12-10 21:52:28 ERROR (MainThread) [homeassistant.components.upnp] Unexpected error fetching Home Hub 3000 Internet Gateway Device data: Error during async_call(), status: 403, body: <html><body><h1>403 Forbidden</h1></body></html>
Traceback (most recent call last):
  File "/srv/homeassistant/lib/python3.8/site-packages/homeassistant/helpers/update_coordinator.py", line 144, in async_refresh
    self.data = await self._async_update_data()
  File "/srv/homeassistant/lib/python3.8/site-packages/homeassistant/helpers/update_coordinator.py", line 132, in _async_update_data
    return await self.update_method()
  File "/srv/homeassistant/lib/python3.8/site-packages/homeassistant/components/upnp/device.py", line 128, in async_get_traffic_data
    values = await asyncio.gather(
  File "/srv/homeassistant/lib/python3.8/site-packages/async_upnp_client/profiles/igd.py", line 110, in async_get_total_packets_received
    result = await action.async_call()
  File "/srv/homeassistant/lib/python3.8/site-packages/async_upnp_client/client.py", line 519, in async_call
    raise UpnpError('Error during async_call(), status: %s, body: %s' %
async_upnp_client.client.UpnpError: Error during async_call(), status: 403, body: <html><body><h1>403 Forbidden</h1></body></html>
2020-12-10 21:52:58 INFO (MainThread) [homeassistant.components.upnp] Fetching Home Hub 3000 Internet Gateway Device data recovered
2020-12-10 23:50:28 ERROR (MainThread) [homeassistant.components.upnp] Unexpected error fetching Home Hub 3000 Internet Gateway Device data: Error during async_call(), status: 403, body: <html><body><h1>403 Forbidden</h1></body></html>
Traceback (most recent call last):
  File "/srv/homeassistant/lib/python3.8/site-packages/homeassistant/helpers/update_coordinator.py", line 144, in async_refresh
    self.data = await self._async_update_data()
  File "/srv/homeassistant/lib/python3.8/site-packages/homeassistant/helpers/update_coordinator.py", line 132, in _async_update_data
    return await self.update_method()
  File "/srv/homeassistant/lib/python3.8/site-packages/homeassistant/components/upnp/device.py", line 128, in async_get_traffic_data
    values = await asyncio.gather(
  File "/srv/homeassistant/lib/python3.8/site-packages/async_upnp_client/profiles/igd.py", line 120, in async_get_total_packets_sent
    result = await action.async_call()
  File "/srv/homeassistant/lib/python3.8/site-packages/async_upnp_client/client.py", line 519, in async_call
    raise UpnpError('Error during async_call(), status: %s, body: %s' %
async_upnp_client.client.UpnpError: Error during async_call(), status: 403, body: <html><body><h1>403 Forbidden</h1></body></html>
2020-12-10 23:50:58 INFO (MainThread) [homeassistant.components.upnp] Fetching Home Hub 3000 Internet Gateway Device data recovered
2020-12-11 00:08:23 INFO (MainThread) [homeassistant.components.websocket_api.http.connection] [1819182032] Connection closed by client
2020-12-11 00:35:22 INFO (MainThread) [homeassistant.components.websocket_api.http.connection] [1717225288] Connection closed by client
2020-12-11 03:56:22 WARNING (Thread-6) [pychromecast.socket_client] [Living Room TV(192.168.1.10):8009] Heartbeat timeout, resetting connection
2020-12-11 03:56:22 INFO (Thread-6) [pychromecast.controllers] Receiver:channel_disconnected
2020-12-11 03:56:48 INFO (Thread-6) [pychromecast.socket_client] [Living Room TV(192.168.1.10):8009] Connection reestablished!
2020-12-11 04:09:03 WARNING (Thread-7) [pychromecast.socket_client] [Kitchen speaker(192.168.1.9):8009] Heartbeat timeout, resetting connection
2020-12-11 04:09:03 INFO (Thread-7) [pychromecast.controllers] Receiver:channel_disconnected
2020-12-11 04:09:18 INFO (Thread-7) [pychromecast.socket_client] [Kitchen speaker(192.168.1.9):8009] Connection reestablished!
2020-12-11 05:29:58 ERROR (MainThread) [homeassistant.components.upnp] Unexpected error fetching Home Hub 3000 Internet Gateway Device data: Error during async_call(), status: 403, body: <html><body><h1>403 Forbidden</h1></body></html>
Traceback (most recent call last):
  File "/srv/homeassistant/lib/python3.8/site-packages/homeassistant/helpers/update_coordinator.py", line 144, in async_refresh
    self.data = await self._async_update_data()
  File "/srv/homeassistant/lib/python3.8/site-packages/homeassistant/helpers/update_coordinator.py", line 132, in _async_update_data
    return await self.update_method()
  File "/srv/homeassistant/lib/python3.8/site-packages/homeassistant/components/upnp/device.py", line 128, in async_get_traffic_data
    values = await asyncio.gather(
  File "/srv/homeassistant/lib/python3.8/site-packages/async_upnp_client/profiles/igd.py", line 120, in async_get_total_packets_sent
    result = await action.async_call()
  File "/srv/homeassistant/lib/python3.8/site-packages/async_upnp_client/client.py", line 519, in async_call
    raise UpnpError('Error during async_call(), status: %s, body: %s' %
async_upnp_client.client.UpnpError: Error during async_call(), status: 403, body: <html><body><h1>403 Forbidden</h1></body></html>
2020-12-11 05:30:28 INFO (MainThread) [homeassistant.components.upnp] Fetching Home Hub 3000 Internet Gateway Device data recovered
2020-12-11 05:56:28 ERROR (MainThread) [homeassistant.components.upnp] Unexpected error fetching Home Hub 3000 Internet Gateway Device data: Error during async_call(), status: 403, body: <html><body><h1>403 Forbidden</h1></body></html>
Traceback (most recent call last):
  File "/srv/homeassistant/lib/python3.8/site-packages/homeassistant/helpers/update_coordinator.py", line 144, in async_refresh
    self.data = await self._async_update_data()
  File "/srv/homeassistant/lib/python3.8/site-packages/homeassistant/helpers/update_coordinator.py", line 132, in _async_update_data
    return await self.update_method()
  File "/srv/homeassistant/lib/python3.8/site-packages/homeassistant/components/upnp/device.py", line 128, in async_get_traffic_data
    values = await asyncio.gather(
  File "/srv/homeassistant/lib/python3.8/site-packages/async_upnp_client/profiles/igd.py", line 120, in async_get_total_packets_sent
    result = await action.async_call()
  File "/srv/homeassistant/lib/python3.8/site-packages/async_upnp_client/client.py", line 519, in async_call
    raise UpnpError('Error during async_call(), status: %s, body: %s' %
async_upnp_client.client.UpnpError: Error during async_call(), status: 403, body: <html><body><h1>403 Forbidden</h1></body></html>
2020-12-11 05:56:58 INFO (MainThread) [homeassistant.components.upnp] Fetching Home Hub 3000 Internet Gateway Device data recovered
2020-12-11 06:53:58 ERROR (MainThread) [homeassistant.components.upnp] Unexpected error fetching Home Hub 3000 Internet Gateway Device data: Error during async_call(), status: 403, body: <html><body><h1>403 Forbidden</h1></body></html>
Traceback (most recent call last):
  File "/srv/homeassistant/lib/python3.8/site-packages/homeassistant/helpers/update_coordinator.py", line 144, in async_refresh
    self.data = await self._async_update_data()
  File "/srv/homeassistant/lib/python3.8/site-packages/homeassistant/helpers/update_coordinator.py", line 132, in _async_update_data
    return await self.update_method()
  File "/srv/homeassistant/lib/python3.8/site-packages/homeassistant/components/upnp/device.py", line 128, in async_get_traffic_data
    values = await asyncio.gather(
  File "/srv/homeassistant/lib/python3.8/site-packages/async_upnp_client/profiles/igd.py", line 99, in async_get_total_bytes_sent
    result = await action.async_call()
  File "/srv/homeassistant/lib/python3.8/site-packages/async_upnp_client/client.py", line 519, in async_call
    raise UpnpError('Error during async_call(), status: %s, body: %s' %
async_upnp_client.client.UpnpError: Error during async_call(), status: 403, body: <html><body><h1>403 Forbidden</h1></body></html>
2020-12-11 06:54:28 INFO (MainThread) [homeassistant.components.upnp] Fetching Home Hub 3000 Internet Gateway Device data recovered
2020-12-11 08:40:58 ERROR (MainThread) [homeassistant.components.upnp] Unexpected error fetching Home Hub 3000 Internet Gateway Device data: Error during async_call(), status: 403, body: <html><body><h1>403 Forbidden</h1></body></html>
Traceback (most recent call last):
  File "/srv/homeassistant/lib/python3.8/site-packages/homeassistant/helpers/update_coordinator.py", line 144, in async_refresh
    self.data = await self._async_update_data()
  File "/srv/homeassistant/lib/python3.8/site-packages/homeassistant/helpers/update_coordinator.py", line 132, in _async_update_data
    return await self.update_method()
  File "/srv/homeassistant/lib/python3.8/site-packages/homeassistant/components/upnp/device.py", line 128, in async_get_traffic_data
    values = await asyncio.gather(
  File "/srv/homeassistant/lib/python3.8/site-packages/async_upnp_client/profiles/igd.py", line 120, in async_get_total_packets_sent
    result = await action.async_call()
  File "/srv/homeassistant/lib/python3.8/site-packages/async_upnp_client/client.py", line 519, in async_call
    raise UpnpError('Error during async_call(), status: %s, body: %s' %
async_upnp_client.client.UpnpError: Error during async_call(), status: 403, body: <html><body><h1>403 Forbidden</h1></body></html>
2020-12-11 08:41:28 INFO (MainThread) [homeassistant.components.upnp] Fetching Home Hub 3000 Internet Gateway Device data recovered
2020-12-11 08:51:28 ERROR (MainThread) [homeassistant.components.upnp] Unexpected error fetching Home Hub 3000 Internet Gateway Device data: Error during async_call(), status: 403, body: <html><body><h1>403 Forbidden</h1></body></html>
Traceback (most recent call last):
  File "/srv/homeassistant/lib/python3.8/site-packages/homeassistant/helpers/update_coordinator.py", line 144, in async_refresh
    self.data = await self._async_update_data()
  File "/srv/homeassistant/lib/python3.8/site-packages/homeassistant/helpers/update_coordinator.py", line 132, in _async_update_data
    return await self.update_method()
  File "/srv/homeassistant/lib/python3.8/site-packages/homeassistant/components/upnp/device.py", line 128, in async_get_traffic_data
    values = await asyncio.gather(
  File "/srv/homeassistant/lib/python3.8/site-packages/async_upnp_client/profiles/igd.py", line 120, in async_get_total_packets_sent
    result = await action.async_call()
  File "/srv/homeassistant/lib/python3.8/site-packages/async_upnp_client/client.py", line 519, in async_call
    raise UpnpError('Error during async_call(), status: %s, body: %s' %
async_upnp_client.client.UpnpError: Error during async_call(), status: 403, body: <html><body><h1>403 Forbidden</h1></body></html>
2020-12-11 08:51:58 INFO (MainThread) [homeassistant.components.upnp] Fetching Home Hub 3000 Internet Gateway Device data recovered
2020-12-11 08:52:28 ERROR (MainThread) [homeassistant.components.upnp] Unexpected error fetching Home Hub 3000 Internet Gateway Device data: Error during async_call(), status: 403, body: <html><body><h1>403 Forbidden</h1></body></html>
Traceback (most recent call last):
  File "/srv/homeassistant/lib/python3.8/site-packages/homeassistant/helpers/update_coordinator.py", line 144, in async_refresh
    self.data = await self._async_update_data()
  File "/srv/homeassistant/lib/python3.8/site-packages/homeassistant/helpers/update_coordinator.py", line 132, in _async_update_data
    return await self.update_method()
  File "/srv/homeassistant/lib/python3.8/site-packages/homeassistant/components/upnp/device.py", line 128, in async_get_traffic_data
    values = await asyncio.gather(
  File "/srv/homeassistant/lib/python3.8/site-packages/async_upnp_client/profiles/igd.py", line 120, in async_get_total_packets_sent
    result = await action.async_call()
  File "/srv/homeassistant/lib/python3.8/site-packages/async_upnp_client/client.py", line 519, in async_call
    raise UpnpError('Error during async_call(), status: %s, body: %s' %
async_upnp_client.client.UpnpError: Error during async_call(), status: 403, body: <html><body><h1>403 Forbidden</h1></body></html>
2020-12-11 08:52:58 INFO (MainThread) [homeassistant.components.upnp] Fetching Home Hub 3000 Internet Gateway Device data recovered
2020-12-11 14:10:48 INFO (MainThread) [homeassistant.components.updater] Submitted analytics to Home Assistant servers. Information submitted includes {}
2020-12-11 14:35:33 ERROR (influxdb) [homeassistant.components.influxdb] Cannot connect to InfluxDB due to 'HTTPConnectionPool(host='192.168.1.4', port=8086): Read timed out. (read timeout=5)'. Please check that the provided connection details (host, port, etc.) are correct and that your InfluxDB server is running and accessible.
2020-12-11 14:36:13 ERROR (influxdb) [homeassistant.components.influxdb] Resumed, lost 30 events.
2020-12-12 02:07:22 WARNING (Thread-6) [pychromecast.socket_client] [Living Room TV(192.168.1.10):8009] Heartbeat timeout, resetting connection
2020-12-12 02:07:22 INFO (Thread-6) [pychromecast.controllers] Receiver:channel_disconnected
2020-12-12 02:07:47 INFO (Thread-6) [pychromecast.socket_client] [Living Room TV(192.168.1.10):8009] Connection reestablished!
2020-12-12 03:16:38 WARNING (Thread-7) [pychromecast.socket_client] [Kitchen speaker(192.168.1.9):8009] Heartbeat timeout, resetting connection
2020-12-12 03:16:38 INFO (Thread-7) [pychromecast.controllers] Receiver:channel_disconnected
2020-12-12 03:16:53 INFO (Thread-7) [pychromecast.socket_client] [Kitchen speaker(192.168.1.9):8009] Connection reestablished!
2020-12-12 09:58:28 ERROR (MainThread) [homeassistant.components.upnp] Unexpected error fetching Home Hub 3000 Internet Gateway Device data: Error during async_call(), status: 403, body: <html><body><h1>403 Forbidden</h1></body></html>
Traceback (most recent call last):
  File "/srv/homeassistant/lib/python3.8/site-packages/homeassistant/helpers/update_coordinator.py", line 144, in async_refresh
    self.data = await self._async_update_data()
  File "/srv/homeassistant/lib/python3.8/site-packages/homeassistant/helpers/update_coordinator.py", line 132, in _async_update_data
    return await self.update_method()
  File "/srv/homeassistant/lib/python3.8/site-packages/homeassistant/components/upnp/device.py", line 128, in async_get_traffic_data
    values = await asyncio.gather(
  File "/srv/homeassistant/lib/python3.8/site-packages/async_upnp_client/profiles/igd.py", line 120, in async_get_total_packets_sent
    result = await action.async_call()
  File "/srv/homeassistant/lib/python3.8/site-packages/async_upnp_client/client.py", line 519, in async_call
    raise UpnpError('Error during async_call(), status: %s, body: %s' %
async_upnp_client.client.UpnpError: Error during async_call(), status: 403, body: <html><body><h1>403 Forbidden</h1></body></html>
2020-12-12 09:58:58 INFO (MainThread) [homeassistant.components.upnp] Fetching Home Hub 3000 Internet Gateway Device data recovered
2020-12-12 10:11:26 ERROR (Thread-6) [pychromecast.socket_client] [Living Room TV(192.168.1.10):8009] Error reading from socket.
2020-12-12 10:11:26 WARNING (Thread-6) [pychromecast.socket_client] [Living Room TV(192.168.1.10):8009] Error communicating with socket, resetting connection
2020-12-12 10:11:26 INFO (Thread-6) [pychromecast.controllers] Receiver:channel_disconnected
2020-12-12 10:11:26 INFO (Thread-6) [pychromecast.socket_client] [Living Room TV(192.168.1.10):8009] Connection reestablished!
2020-12-12 10:12:28 ERROR (Thread-6) [pychromecast.socket_client] [Living Room TV(192.168.1.10):8009] Error reading from socket.
2020-12-12 10:12:28 WARNING (Thread-6) [pychromecast.socket_client] [Living Room TV(192.168.1.10):8009] Error communicating with socket, resetting connection
2020-12-12 10:12:28 INFO (Thread-6) [pychromecast.controllers] Receiver:channel_disconnected
2020-12-12 10:12:29 INFO (Thread-6) [pychromecast.socket_client] [Living Room TV(192.168.1.10):8009] Connection reestablished!
2020-12-12 14:01:29 ERROR (MainThread) [homeassistant.components.upnp] Unexpected error fetching Home Hub 3000 Internet Gateway Device data: Error during async_call(), status: 403, body: <html><body><h1>403 Forbidden</h1></body></html>
Traceback (most recent call last):
  File "/srv/homeassistant/lib/python3.8/site-packages/homeassistant/helpers/update_coordinator.py", line 144, in async_refresh
    self.data = await self._async_update_data()
  File "/srv/homeassistant/lib/python3.8/site-packages/homeassistant/helpers/update_coordinator.py", line 132, in _async_update_data
    return await self.update_method()
  File "/srv/homeassistant/lib/python3.8/site-packages/homeassistant/components/upnp/device.py", line 128, in async_get_traffic_data
    values = await asyncio.gather(
  File "/srv/homeassistant/lib/python3.8/site-packages/async_upnp_client/profiles/igd.py", line 110, in async_get_total_packets_received
    result = await action.async_call()
  File "/srv/homeassistant/lib/python3.8/site-packages/async_upnp_client/client.py", line 519, in async_call
    raise UpnpError('Error during async_call(), status: %s, body: %s' %
async_upnp_client.client.UpnpError: Error during async_call(), status: 403, body: <html><body><h1>403 Forbidden</h1></body></html>
2020-12-12 14:01:59 INFO (MainThread) [homeassistant.components.upnp] Fetching Home Hub 3000 Internet Gateway Device data recovered
2020-12-12 14:10:48 INFO (MainThread) [homeassistant.components.updater] Submitted analytics to Home Assistant servers. Information submitted includes {}
2020-12-12 14:18:06 INFO (MainThread) [homeassistant.components.websocket_api.http.connection] [1767836160] Connection closed by client
2020-12-12 14:35:59 ERROR (MainThread) [homeassistant.components.upnp] Unexpected error fetching Home Hub 3000 Internet Gateway Device data: Error during async_call(), status: 403, body: <html><body><h1>403 Forbidden</h1></body></html>
Traceback (most recent call last):
  File "/srv/homeassistant/lib/python3.8/site-packages/homeassistant/helpers/update_coordinator.py", line 144, in async_refresh
    self.data = await self._async_update_data()
  File "/srv/homeassistant/lib/python3.8/site-packages/homeassistant/helpers/update_coordinator.py", line 132, in _async_update_data
    return await self.update_method()
  File "/srv/homeassistant/lib/python3.8/site-packages/homeassistant/components/upnp/device.py", line 128, in async_get_traffic_data
    values = await asyncio.gather(
  File "/srv/homeassistant/lib/python3.8/site-packages/async_upnp_client/profiles/igd.py", line 120, in async_get_total_packets_sent
    result = await action.async_call()
  File "/srv/homeassistant/lib/python3.8/site-packages/async_upnp_client/client.py", line 519, in async_call
    raise UpnpError('Error during async_call(), status: %s, body: %s' %
async_upnp_client.client.UpnpError: Error during async_call(), status: 403, body: <html><body><h1>403 Forbidden</h1></body></html>
2020-12-12 14:36:29 INFO (MainThread) [homeassistant.components.upnp] Fetching Home Hub 3000 Internet Gateway Device data recovered
2020-12-12 18:03:47 INFO (MainThread) [homeassistant.components.websocket_api.http.connection] [1717225696] Connection closed by client
2020-12-12 18:20:59 ERROR (MainThread) [homeassistant.components.upnp] Unexpected error fetching Home Hub 3000 Internet Gateway Device data: Error during async_call(), status: 403, body: <html><body><h1>403 Forbidden</h1></body></html>
Traceback (most recent call last):
  File "/srv/homeassistant/lib/python3.8/site-packages/homeassistant/helpers/update_coordinator.py", line 144, in async_refresh
    self.data = await self._async_update_data()
  File "/srv/homeassistant/lib/python3.8/site-packages/homeassistant/helpers/update_coordinator.py", line 132, in _async_update_data
    return await self.update_method()
  File "/srv/homeassistant/lib/python3.8/site-packages/homeassistant/components/upnp/device.py", line 128, in async_get_traffic_data
    values = await asyncio.gather(
  File "/srv/homeassistant/lib/python3.8/site-packages/async_upnp_client/profiles/igd.py", line 120, in async_get_total_packets_sent
    result = await action.async_call()
  File "/srv/homeassistant/lib/python3.8/site-packages/async_upnp_client/client.py", line 519, in async_call
    raise UpnpError('Error during async_call(), status: %s, body: %s' %
async_upnp_client.client.UpnpError: Error during async_call(), status: 403, body: <html><body><h1>403 Forbidden</h1></body></html>
2020-12-12 18:21:29 INFO (MainThread) [homeassistant.components.upnp] Fetching Home Hub 3000 Internet Gateway Device data recovered
2020-12-12 20:29:29 ERROR (MainThread) [homeassistant.components.upnp] Unexpected error fetching Home Hub 3000 Internet Gateway Device data: Error during async_call(), status: 403, body: <html><body><h1>403 Forbidden</h1></body></html>
Traceback (most recent call last):
  File "/srv/homeassistant/lib/python3.8/site-packages/homeassistant/helpers/update_coordinator.py", line 144, in async_refresh
    self.data = await self._async_update_data()
  File "/srv/homeassistant/lib/python3.8/site-packages/homeassistant/helpers/update_coordinator.py", line 132, in _async_update_data
    return await self.update_method()
  File "/srv/homeassistant/lib/python3.8/site-packages/homeassistant/components/upnp/device.py", line 128, in async_get_traffic_data
    values = await asyncio.gather(
  File "/srv/homeassistant/lib/python3.8/site-packages/async_upnp_client/profiles/igd.py", line 120, in async_get_total_packets_sent
    result = await action.async_call()
  File "/srv/homeassistant/lib/python3.8/site-packages/async_upnp_client/client.py", line 519, in async_call
    raise UpnpError('Error during async_call(), status: %s, body: %s' %
async_upnp_client.client.UpnpError: Error during async_call(), status: 403, body: <html><body><h1>403 Forbidden</h1></body></html>
2020-12-12 20:29:59 INFO (MainThread) [homeassistant.components.upnp] Fetching Home Hub 3000 Internet Gateway Device data recovered
2020-12-13 01:47:29 ERROR (MainThread) [homeassistant.components.upnp] Unexpected error fetching Home Hub 3000 Internet Gateway Device data: Error during async_call(), status: 403, body: <html><body><h1>403 Forbidden</h1></body></html>
Traceback (most recent call last):
  File "/srv/homeassistant/lib/python3.8/site-packages/homeassistant/helpers/update_coordinator.py", line 144, in async_refresh
    self.data = await self._async_update_data()
  File "/srv/homeassistant/lib/python3.8/site-packages/homeassistant/helpers/update_coordinator.py", line 132, in _async_update_data
    return await self.update_method()
  File "/srv/homeassistant/lib/python3.8/site-packages/homeassistant/components/upnp/device.py", line 128, in async_get_traffic_data
    values = await asyncio.gather(
  File "/srv/homeassistant/lib/python3.8/site-packages/async_upnp_client/profiles/igd.py", line 99, in async_get_total_bytes_sent
    result = await action.async_call()
  File "/srv/homeassistant/lib/python3.8/site-packages/async_upnp_client/client.py", line 519, in async_call
    raise UpnpError('Error during async_call(), status: %s, body: %s' %
async_upnp_client.client.UpnpError: Error during async_call(), status: 403, body: <html><body><h1>403 Forbidden</h1></body></html>
2020-12-13 01:47:59 INFO (MainThread) [homeassistant.components.upnp] Fetching Home Hub 3000 Internet Gateway Device data recovered
2020-12-13 02:32:32 WARNING (Thread-6) [pychromecast.socket_client] [Living Room TV(192.168.1.10):8009] Heartbeat timeout, resetting connection
2020-12-13 02:32:32 INFO (Thread-6) [pychromecast.controllers] Receiver:channel_disconnected
2020-12-13 02:32:52 INFO (Thread-6) [pychromecast.socket_client] [Living Room TV(192.168.1.10):8009] Connection reestablished!
2020-12-13 02:43:09 WARNING (Thread-7) [pychromecast.socket_client] [Kitchen speaker(192.168.1.9):8009] Heartbeat timeout, resetting connection
2020-12-13 02:43:09 INFO (Thread-7) [pychromecast.controllers] Receiver:channel_disconnected
2020-12-13 02:43:29 INFO (Thread-7) [pychromecast.socket_client] [Kitchen speaker(192.168.1.9):8009] Connection reestablished!
2020-12-13 03:26:41 INFO (MainThread) [homeassistant.components.websocket_api.http.connection] [1777718656] Connection closed by client
2020-12-13 04:06:29 ERROR (MainThread) [homeassistant.components.upnp] Unexpected error fetching Home Hub 3000 Internet Gateway Device data: Error during async_call(), status: 403, body: <html><body><h1>403 Forbidden</h1></body></html>
Traceback (most recent call last):
  File "/srv/homeassistant/lib/python3.8/site-packages/homeassistant/helpers/update_coordinator.py", line 144, in async_refresh
    self.data = await self._async_update_data()
  File "/srv/homeassistant/lib/python3.8/site-packages/homeassistant/helpers/update_coordinator.py", line 132, in _async_update_data
    return await self.update_method()
  File "/srv/homeassistant/lib/python3.8/site-packages/homeassistant/components/upnp/device.py", line 128, in async_get_traffic_data
    values = await asyncio.gather(
  File "/srv/homeassistant/lib/python3.8/site-packages/async_upnp_client/profiles/igd.py", line 110, in async_get_total_packets_received
    result = await action.async_call()
  File "/srv/homeassistant/lib/python3.8/site-packages/async_upnp_client/client.py", line 519, in async_call
    raise UpnpError('Error during async_call(), status: %s, body: %s' %
async_upnp_client.client.UpnpError: Error during async_call(), status: 403, body: <html><body><h1>403 Forbidden</h1></body></html>
2020-12-13 04:06:59 INFO (MainThread) [homeassistant.components.upnp] Fetching Home Hub 3000 Internet Gateway Device data recovered
2020-12-13 07:26:29 ERROR (MainThread) [homeassistant.components.upnp] Unexpected error fetching Home Hub 3000 Internet Gateway Device data: Error during async_call(), status: 403, body: <html><body><h1>403 Forbidden</h1></body></html>
Traceback (most recent call last):
  File "/srv/homeassistant/lib/python3.8/site-packages/homeassistant/helpers/update_coordinator.py", line 144, in async_refresh
    self.data = await self._async_update_data()
  File "/srv/homeassistant/lib/python3.8/site-packages/homeassistant/helpers/update_coordinator.py", line 132, in _async_update_data
    return await self.update_method()
  File "/srv/homeassistant/lib/python3.8/site-packages/homeassistant/components/upnp/device.py", line 128, in async_get_traffic_data
    values = await asyncio.gather(
  File "/srv/homeassistant/lib/python3.8/site-packages/async_upnp_client/profiles/igd.py", line 120, in async_get_total_packets_sent
    result = await action.async_call()
  File "/srv/homeassistant/lib/python3.8/site-packages/async_upnp_client/client.py", line 519, in async_call
    raise UpnpError('Error during async_call(), status: %s, body: %s' %
async_upnp_client.client.UpnpError: Error during async_call(), status: 403, body: <html><body><h1>403 Forbidden</h1></body></html>
2020-12-13 07:26:59 INFO (MainThread) [homeassistant.components.upnp] Fetching Home Hub 3000 Internet Gateway Device data recovered
2020-12-13 11:48:59 ERROR (MainThread) [homeassistant.components.upnp] Unexpected error fetching Home Hub 3000 Internet Gateway Device data: Error during async_call(), status: 403, body: <html><body><h1>403 Forbidden</h1></body></html>
Traceback (most recent call last):
  File "/srv/homeassistant/lib/python3.8/site-packages/homeassistant/helpers/update_coordinator.py", line 144, in async_refresh
    self.data = await self._async_update_data()
  File "/srv/homeassistant/lib/python3.8/site-packages/homeassistant/helpers/update_coordinator.py", line 132, in _async_update_data
    return await self.update_method()
  File "/srv/homeassistant/lib/python3.8/site-packages/homeassistant/components/upnp/device.py", line 128, in async_get_traffic_data
    values = await asyncio.gather(
  File "/srv/homeassistant/lib/python3.8/site-packages/async_upnp_client/profiles/igd.py", line 120, in async_get_total_packets_sent
    result = await action.async_call()
  File "/srv/homeassistant/lib/python3.8/site-packages/async_upnp_client/client.py", line 519, in async_call
    raise UpnpError('Error during async_call(), status: %s, body: %s' %
async_upnp_client.client.UpnpError: Error during async_call(), status: 403, body: <html><body><h1>403 Forbidden</h1></body></html>
2020-12-13 11:49:29 INFO (MainThread) [homeassistant.components.upnp] Fetching Home Hub 3000 Internet Gateway Device data recovered
2020-12-13 12:15:59 ERROR (MainThread) [homeassistant.components.upnp] Unexpected error fetching Home Hub 3000 Internet Gateway Device data: Error during async_call(), status: 403, body: <html><body><h1>403 Forbidden</h1></body></html>
Traceback (most recent call last):
  File "/srv/homeassistant/lib/python3.8/site-packages/homeassistant/helpers/update_coordinator.py", line 144, in async_refresh
    self.data = await self._async_update_data()
  File "/srv/homeassistant/lib/python3.8/site-packages/homeassistant/helpers/update_coordinator.py", line 132, in _async_update_data
    return await self.update_method()
  File "/srv/homeassistant/lib/python3.8/site-packages/homeassistant/components/upnp/device.py", line 128, in async_get_traffic_data
    values = await asyncio.gather(
  File "/srv/homeassistant/lib/python3.8/site-packages/async_upnp_client/profiles/igd.py", line 110, in async_get_total_packets_received
    result = await action.async_call()
  File "/srv/homeassistant/lib/python3.8/site-packages/async_upnp_client/client.py", line 519, in async_call
    raise UpnpError('Error during async_call(), status: %s, body: %s' %
async_upnp_client.client.UpnpError: Error during async_call(), status: 403, body: <html><body><h1>403 Forbidden</h1></body></html>
2020-12-13 12:16:29 INFO (MainThread) [homeassistant.components.upnp] Fetching Home Hub 3000 Internet Gateway Device data recovered
2020-12-13 12:31:27 ERROR (Thread-6727) [root] Uncaught thread exception
Traceback (most recent call last):
  File "/usr/local/lib/python3.8/threading.py", line 932, in _bootstrap_inner
    self.run()
  File "/srv/homeassistant/lib/python3.8/site-packages/speedtest.py", line 905, in run
    f = self._opener(request)
  File "/usr/local/lib/python3.8/urllib/request.py", line 525, in open
    response = self._open(req, data)
  File "/usr/local/lib/python3.8/urllib/request.py", line 542, in _open
    result = self._call_chain(self.handle_open, protocol, protocol +
  File "/usr/local/lib/python3.8/urllib/request.py", line 502, in _call_chain
    result = func(*args)
  File "/srv/homeassistant/lib/python3.8/site-packages/speedtest.py", line 537, in http_open
    return self.do_open(
  File "/usr/local/lib/python3.8/urllib/request.py", line 1354, in do_open
    r = h.getresponse()
  File "/usr/local/lib/python3.8/http/client.py", line 1347, in getresponse
    response.begin()
  File "/usr/local/lib/python3.8/http/client.py", line 307, in begin
    version, status, reason = self._read_status()
  File "/usr/local/lib/python3.8/http/client.py", line 289, in _read_status
    raise BadStatusLine(line)
http.client.BadStatusLine:  ®Áµîª¿ÖgôË´<bD>HTTP/1.1 200 OK

2020-12-13 12:31:31 ERROR (MainThread) [homeassistant.components.speedtestdotnet] Unexpected error fetching speedtestdotnet data: unsupported operand type(s) for +: 'int' and 'NoneType'
Traceback (most recent call last):
  File "/srv/homeassistant/lib/python3.8/site-packages/homeassistant/helpers/update_coordinator.py", line 144, in async_refresh
    self.data = await self._async_update_data()
  File "/srv/homeassistant/lib/python3.8/site-packages/homeassistant/helpers/update_coordinator.py", line 132, in _async_update_data
    return await self.update_method()
  File "/srv/homeassistant/lib/python3.8/site-packages/homeassistant/components/speedtestdotnet/__init__.py", line 174, in async_update
    return await self.hass.async_add_executor_job(self.update_data)
  File "/usr/local/lib/python3.8/concurrent/futures/thread.py", line 57, in run
    result = self.fn(*self.args, **self.kwargs)
  File "/srv/homeassistant/lib/python3.8/site-packages/homeassistant/components/speedtestdotnet/__init__.py", line 168, in update_data
    self.api.upload()
  File "/srv/homeassistant/lib/python3.8/site-packages/speedtest.py", line 1664, in upload
    self.results.bytes_sent = sum(finished)
TypeError: unsupported operand type(s) for +: 'int' and 'NoneType'
2020-12-13 12:35:17 INFO (MainThread) [homeassistant.components.websocket_api.http.connection] [1776733224] Connection closed by client
2020-12-13 13:31:48 INFO (MainThread) [homeassistant.components.speedtestdotnet] Fetching speedtestdotnet data recovered
2020-12-13 14:10:48 INFO (MainThread) [homeassistant.components.updater] Submitted analytics to Home Assistant servers. Information submitted includes {}
2020-12-13 16:54:59 ERROR (MainThread) [homeassistant.components.upnp] Unexpected error fetching Home Hub 3000 Internet Gateway Device data: Error during async_call(), status: 403, body: <html><body><h1>403 Forbidden</h1></body></html>
Traceback (most recent call last):
  File "/srv/homeassistant/lib/python3.8/site-packages/homeassistant/helpers/update_coordinator.py", line 144, in async_refresh
    self.data = await self._async_update_data()
  File "/srv/homeassistant/lib/python3.8/site-packages/homeassistant/helpers/update_coordinator.py", line 132, in _async_update_data
    return await self.update_method()
  File "/srv/homeassistant/lib/python3.8/site-packages/homeassistant/components/upnp/device.py", line 128, in async_get_traffic_data
    values = await asyncio.gather(
  File "/srv/homeassistant/lib/python3.8/site-packages/async_upnp_client/profiles/igd.py", line 120, in async_get_total_packets_sent
    result = await action.async_call()
  File "/srv/homeassistant/lib/python3.8/site-packages/async_upnp_client/client.py", line 519, in async_call
    raise UpnpError('Error during async_call(), status: %s, body: %s' %
async_upnp_client.client.UpnpError: Error during async_call(), status: 403, body: <html><body><h1>403 Forbidden</h1></body></html>
2020-12-13 16:55:29 INFO (MainThread) [homeassistant.components.upnp] Fetching Home Hub 3000 Internet Gateway Device data recovered
2020-12-13 18:57:46 INFO (MainThread) [homeassistant.components.websocket_api.http.connection] [1776668312] Connection closed by client
2020-12-14 04:09:21 WARNING (Thread-6) [pychromecast.socket_client] [Living Room TV(192.168.1.10):8009] Heartbeat timeout, resetting connection
2020-12-14 04:09:21 INFO (Thread-6) [pychromecast.controllers] Receiver:channel_disconnected
2020-12-14 04:09:46 INFO (Thread-6) [pychromecast.socket_client] [Living Room TV(192.168.1.10):8009] Connection reestablished!
2020-12-14 04:42:17 WARNING (Thread-7) [pychromecast.socket_client] [Kitchen speaker(192.168.1.9):8009] Heartbeat timeout, resetting connection
2020-12-14 04:42:17 INFO (Thread-7) [pychromecast.controllers] Receiver:channel_disconnected
2020-12-14 04:42:38 INFO (Thread-7) [pychromecast.socket_client] [Kitchen speaker(192.168.1.9):8009] Connection reestablished!
2020-12-14 09:18:29 ERROR (MainThread) [homeassistant.components.upnp] Unexpected error fetching Home Hub 3000 Internet Gateway Device data: Error during async_call(), status: 403, body: <html><body><h1>403 Forbidden</h1></body></html>
Traceback (most recent call last):
  File "/srv/homeassistant/lib/python3.8/site-packages/homeassistant/helpers/update_coordinator.py", line 144, in async_refresh
    self.data = await self._async_update_data()
  File "/srv/homeassistant/lib/python3.8/site-packages/homeassistant/helpers/update_coordinator.py", line 132, in _async_update_data
    return await self.update_method()
  File "/srv/homeassistant/lib/python3.8/site-packages/homeassistant/components/upnp/device.py", line 128, in async_get_traffic_data
    values = await asyncio.gather(
  File "/srv/homeassistant/lib/python3.8/site-packages/async_upnp_client/profiles/igd.py", line 120, in async_get_total_packets_sent
    result = await action.async_call()
  File "/srv/homeassistant/lib/python3.8/site-packages/async_upnp_client/client.py", line 519, in async_call
    raise UpnpError('Error during async_call(), status: %s, body: %s' %
async_upnp_client.client.UpnpError: Error during async_call(), status: 403, body: <html><body><h1>403 Forbidden</h1></body></html>
2020-12-14 09:18:59 INFO (MainThread) [homeassistant.components.upnp] Fetching Home Hub 3000 Internet Gateway Device data recovered
2020-12-14 10:47:29 ERROR (MainThread) [homeassistant.components.upnp] Unexpected error fetching Home Hub 3000 Internet Gateway Device data: Error during async_call(), status: 403, body: <html><body><h1>403 Forbidden</h1></body></html>
Traceback (most recent call last):
  File "/srv/homeassistant/lib/python3.8/site-packages/homeassistant/helpers/update_coordinator.py", line 144, in async_refresh
    self.data = await self._async_update_data()
  File "/srv/homeassistant/lib/python3.8/site-packages/homeassistant/helpers/update_coordinator.py", line 132, in _async_update_data
    return await self.update_method()
  File "/srv/homeassistant/lib/python3.8/site-packages/homeassistant/components/upnp/device.py", line 128, in async_get_traffic_data
    values = await asyncio.gather(
  File "/srv/homeassistant/lib/python3.8/site-packages/async_upnp_client/profiles/igd.py", line 120, in async_get_total_packets_sent
    result = await action.async_call()
  File "/srv/homeassistant/lib/python3.8/site-packages/async_upnp_client/client.py", line 519, in async_call
    raise UpnpError('Error during async_call(), status: %s, body: %s' %
async_upnp_client.client.UpnpError: Error during async_call(), status: 403, body: <html><body><h1>403 Forbidden</h1></body></html>
2020-12-14 10:47:59 INFO (MainThread) [homeassistant.components.upnp] Fetching Home Hub 3000 Internet Gateway Device data recovered
2020-12-14 11:13:29 ERROR (MainThread) [homeassistant.components.upnp] Unexpected error fetching Home Hub 3000 Internet Gateway Device data: Error during async_call(), status: 403, body: <html><body><h1>403 Forbidden</h1></body></html>
Traceback (most recent call last):
  File "/srv/homeassistant/lib/python3.8/site-packages/homeassistant/helpers/update_coordinator.py", line 144, in async_refresh
    self.data = await self._async_update_data()
  File "/srv/homeassistant/lib/python3.8/site-packages/homeassistant/helpers/update_coordinator.py", line 132, in _async_update_data
    return await self.update_method()
  File "/srv/homeassistant/lib/python3.8/site-packages/homeassistant/components/upnp/device.py", line 128, in async_get_traffic_data
    values = await asyncio.gather(
  File "/srv/homeassistant/lib/python3.8/site-packages/async_upnp_client/profiles/igd.py", line 110, in async_get_total_packets_received
    result = await action.async_call()
  File "/srv/homeassistant/lib/python3.8/site-packages/async_upnp_client/client.py", line 519, in async_call
    raise UpnpError('Error during async_call(), status: %s, body: %s' %
async_upnp_client.client.UpnpError: Error during async_call(), status: 403, body: <html><body><h1>403 Forbidden</h1></body></html>
2020-12-14 11:13:59 INFO (MainThread) [homeassistant.components.upnp] Fetching Home Hub 3000 Internet Gateway Device data recovered
2020-12-14 11:53:29 ERROR (MainThread) [homeassistant.components.upnp] Unexpected error fetching Home Hub 3000 Internet Gateway Device data: Error during async_call(), status: 403, body: <html><body><h1>403 Forbidden</h1></body></html>
Traceback (most recent call last):
  File "/srv/homeassistant/lib/python3.8/site-packages/homeassistant/helpers/update_coordinator.py", line 144, in async_refresh
    self.data = await self._async_update_data()
  File "/srv/homeassistant/lib/python3.8/site-packages/homeassistant/helpers/update_coordinator.py", line 132, in _async_update_data
    return await self.update_method()
  File "/srv/homeassistant/lib/python3.8/site-packages/homeassistant/components/upnp/device.py", line 128, in async_get_traffic_data
    values = await asyncio.gather(
  File "/srv/homeassistant/lib/python3.8/site-packages/async_upnp_client/profiles/igd.py", line 120, in async_get_total_packets_sent
    result = await action.async_call()
  File "/srv/homeassistant/lib/python3.8/site-packages/async_upnp_client/client.py", line 519, in async_call
    raise UpnpError('Error during async_call(), status: %s, body: %s' %
async_upnp_client.client.UpnpError: Error during async_call(), status: 403, body: <html><body><h1>403 Forbidden</h1></body></html>
2020-12-14 11:53:59 INFO (MainThread) [homeassistant.components.upnp] Fetching Home Hub 3000 Internet Gateway Device data recovered
2020-12-14 14:10:48 INFO (MainThread) [homeassistant.components.updater] Submitted analytics to Home Assistant servers. Information submitted includes {}
2020-12-14 16:44:08 INFO (MainThread) [homeassistant.components.websocket_api.http.connection] [1767881912] Connection closed by client
2020-12-14 20:19:00 ERROR (MainThread) [homeassistant.components.upnp] Unexpected error fetching Home Hub 3000 Internet Gateway Device data: Error during async_call(), status: 403, body: <html><body><h1>403 Forbidden</h1></body></html>
Traceback (most recent call last):
  File "/srv/homeassistant/lib/python3.8/site-packages/homeassistant/helpers/update_coordinator.py", line 144, in async_refresh
    self.data = await self._async_update_data()
  File "/srv/homeassistant/lib/python3.8/site-packages/homeassistant/helpers/update_coordinator.py", line 132, in _async_update_data
    return await self.update_method()
  File "/srv/homeassistant/lib/python3.8/site-packages/homeassistant/components/upnp/device.py", line 128, in async_get_traffic_data
    values = await asyncio.gather(
  File "/srv/homeassistant/lib/python3.8/site-packages/async_upnp_client/profiles/igd.py", line 110, in async_get_total_packets_received
    result = await action.async_call()
  File "/srv/homeassistant/lib/python3.8/site-packages/async_upnp_client/client.py", line 519, in async_call
    raise UpnpError('Error during async_call(), status: %s, body: %s' %
async_upnp_client.client.UpnpError: Error during async_call(), status: 403, body: <html><body><h1>403 Forbidden</h1></body></html>
2020-12-14 20:19:30 INFO (MainThread) [homeassistant.components.upnp] Fetching Home Hub 3000 Internet Gateway Device data recovered
2020-12-15 01:49:00 ERROR (MainThread) [homeassistant.components.upnp] Unexpected error fetching Home Hub 3000 Internet Gateway Device data: Error during async_call(), status: 403, body: <html><body><h1>403 Forbidden</h1></body></html>
Traceback (most recent call last):
  File "/srv/homeassistant/lib/python3.8/site-packages/homeassistant/helpers/update_coordinator.py", line 144, in async_refresh
    self.data = await self._async_update_data()
  File "/srv/homeassistant/lib/python3.8/site-packages/homeassistant/helpers/update_coordinator.py", line 132, in _async_update_data
    return await self.update_method()
  File "/srv/homeassistant/lib/python3.8/site-packages/homeassistant/components/upnp/device.py", line 128, in async_get_traffic_data
    values = await asyncio.gather(
  File "/srv/homeassistant/lib/python3.8/site-packages/async_upnp_client/profiles/igd.py", line 120, in async_get_total_packets_sent
    result = await action.async_call()
  File "/srv/homeassistant/lib/python3.8/site-packages/async_upnp_client/client.py", line 519, in async_call
    raise UpnpError('Error during async_call(), status: %s, body: %s' %
async_upnp_client.client.UpnpError: Error during async_call(), status: 403, body: <html><body><h1>403 Forbidden</h1></body></html>
2020-12-15 01:49:30 INFO (MainThread) [homeassistant.components.upnp] Fetching Home Hub 3000 Internet Gateway Device data recovered
2020-12-15 02:36:01 WARNING (MainThread) [homeassistant.helpers.entity] Update of sensor.dark_sky_summary is taking over 10 seconds
2020-12-15 02:36:01 ERROR (SyncWorker_3) [homeassistant.components.darksky.sensor] Unable to connect to Dark Sky: HTTPSConnectionPool(host='api.darksky.net', port=443): Max retries exceeded with url: /forecast/fd7b714a19bd3e9096385e4c254101a5/44.6491705,-63.6263283?units=si&lang=en (Caused by NewConnectionError('<urllib3.connection.HTTPSConnection object at 0x6a98d358>: Failed to establish a new connection: [Errno -3] Temporary failure in name resolution'))
2020-12-15 02:45:51 INFO (SyncWorker_3) [homeassistant.components.darksky.sensor] Reconnected to Dark Sky
2020-12-15 03:21:41 WARNING (Thread-6) [pychromecast.socket_client] [Living Room TV(192.168.1.10):8009] Heartbeat timeout, resetting connection
2020-12-15 03:21:41 INFO (Thread-6) [pychromecast.controllers] Receiver:channel_disconnected
2020-12-15 03:21:57 INFO (Thread-6) [pychromecast.socket_client] [Living Room TV(192.168.1.10):8009] Connection reestablished!
2020-12-15 04:53:21 WARNING (Thread-7) [pychromecast.socket_client] [Kitchen speaker(192.168.1.9):8009] Heartbeat timeout, resetting connection
2020-12-15 04:53:21 INFO (Thread-7) [pychromecast.controllers] Receiver:channel_disconnected
2020-12-15 04:53:36 INFO (Thread-7) [pychromecast.socket_client] [Kitchen speaker(192.168.1.9):8009] Connection reestablished!
2020-12-15 05:08:30 ERROR (MainThread) [homeassistant.components.upnp] Unexpected error fetching Home Hub 3000 Internet Gateway Device data: Error during async_call(), status: 403, body: <html><body><h1>403 Forbidden</h1></body></html>
Traceback (most recent call last):
  File "/srv/homeassistant/lib/python3.8/site-packages/homeassistant/helpers/update_coordinator.py", line 144, in async_refresh
    self.data = await self._async_update_data()
  File "/srv/homeassistant/lib/python3.8/site-packages/homeassistant/helpers/update_coordinator.py", line 132, in _async_update_data
    return await self.update_method()
  File "/srv/homeassistant/lib/python3.8/site-packages/homeassistant/components/upnp/device.py", line 128, in async_get_traffic_data
    values = await asyncio.gather(
  File "/srv/homeassistant/lib/python3.8/site-packages/async_upnp_client/profiles/igd.py", line 110, in async_get_total_packets_received
    result = await action.async_call()
  File "/srv/homeassistant/lib/python3.8/site-packages/async_upnp_client/client.py", line 519, in async_call
    raise UpnpError('Error during async_call(), status: %s, body: %s' %
async_upnp_client.client.UpnpError: Error during async_call(), status: 403, body: <html><body><h1>403 Forbidden</h1></body></html>
2020-12-15 05:09:00 INFO (MainThread) [homeassistant.components.upnp] Fetching Home Hub 3000 Internet Gateway Device data recovered
2020-12-15 06:45:30 ERROR (MainThread) [homeassistant.components.upnp] Unexpected error fetching Home Hub 3000 Internet Gateway Device data: Error during async_call(), status: 403, body: <html><body><h1>403 Forbidden</h1></body></html>
Traceback (most recent call last):
  File "/srv/homeassistant/lib/python3.8/site-packages/homeassistant/helpers/update_coordinator.py", line 144, in async_refresh
    self.data = await self._async_update_data()
  File "/srv/homeassistant/lib/python3.8/site-packages/homeassistant/helpers/update_coordinator.py", line 132, in _async_update_data
    return await self.update_method()
  File "/srv/homeassistant/lib/python3.8/site-packages/homeassistant/components/upnp/device.py", line 128, in async_get_traffic_data
    values = await asyncio.gather(
  File "/srv/homeassistant/lib/python3.8/site-packages/async_upnp_client/profiles/igd.py", line 110, in async_get_total_packets_received
    result = await action.async_call()
  File "/srv/homeassistant/lib/python3.8/site-packages/async_upnp_client/client.py", line 519, in async_call
    raise UpnpError('Error during async_call(), status: %s, body: %s' %
async_upnp_client.client.UpnpError: Error during async_call(), status: 403, body: <html><body><h1>403 Forbidden</h1></body></html>
2020-12-15 06:46:00 INFO (MainThread) [homeassistant.components.upnp] Fetching Home Hub 3000 Internet Gateway Device data recovered
2020-12-15 13:13:00 ERROR (MainThread) [homeassistant.components.upnp] Unexpected error fetching Home Hub 3000 Internet Gateway Device data: Error during async_call(), status: 403, body: <html><body><h1>403 Forbidden</h1></body></html>
Traceback (most recent call last):
  File "/srv/homeassistant/lib/python3.8/site-packages/homeassistant/helpers/update_coordinator.py", line 144, in async_refresh
    self.data = await self._async_update_data()
  File "/srv/homeassistant/lib/python3.8/site-packages/homeassistant/helpers/update_coordinator.py", line 132, in _async_update_data
    return await self.update_method()
  File "/srv/homeassistant/lib/python3.8/site-packages/homeassistant/components/upnp/device.py", line 128, in async_get_traffic_data
    values = await asyncio.gather(
  File "/srv/homeassistant/lib/python3.8/site-packages/async_upnp_client/profiles/igd.py", line 110, in async_get_total_packets_received
    result = await action.async_call()
  File "/srv/homeassistant/lib/python3.8/site-packages/async_upnp_client/client.py", line 519, in async_call
    raise UpnpError('Error during async_call(), status: %s, body: %s' %
async_upnp_client.client.UpnpError: Error during async_call(), status: 403, body: <html><body><h1>403 Forbidden</h1></body></html>
2020-12-15 13:13:30 INFO (MainThread) [homeassistant.components.upnp] Fetching Home Hub 3000 Internet Gateway Device data recovered
2020-12-15 13:41:13 INFO (MainThread) [homeassistant.components.websocket_api.http.connection] [1786520816] Connection closed by client
2020-12-15 13:48:41 INFO (MainThread) [homeassistant.components.websocket_api.http.connection] [1767803992] Connection closed by client
2020-12-15 14:10:48 INFO (MainThread) [homeassistant.components.updater] Submitted analytics to Home Assistant servers. Information submitted includes {}
2020-12-15 14:11:00 ERROR (MainThread) [homeassistant.components.upnp] Unexpected error fetching Home Hub 3000 Internet Gateway Device data: Error during async_call(), status: 403, body: <html><body><h1>403 Forbidden</h1></body></html>
Traceback (most recent call last):
  File "/srv/homeassistant/lib/python3.8/site-packages/homeassistant/helpers/update_coordinator.py", line 144, in async_refresh
    self.data = await self._async_update_data()
  File "/srv/homeassistant/lib/python3.8/site-packages/homeassistant/helpers/update_coordinator.py", line 132, in _async_update_data
    return await self.update_method()
  File "/srv/homeassistant/lib/python3.8/site-packages/homeassistant/components/upnp/device.py", line 128, in async_get_traffic_data
    values = await asyncio.gather(
  File "/srv/homeassistant/lib/python3.8/site-packages/async_upnp_client/profiles/igd.py", line 120, in async_get_total_packets_sent
    result = await action.async_call()
  File "/srv/homeassistant/lib/python3.8/site-packages/async_upnp_client/client.py", line 519, in async_call
    raise UpnpError('Error during async_call(), status: %s, body: %s' %
async_upnp_client.client.UpnpError: Error during async_call(), status: 403, body: <html><body><h1>403 Forbidden</h1></body></html>
2020-12-15 14:11:30 INFO (MainThread) [homeassistant.components.upnp] Fetching Home Hub 3000 Internet Gateway Device data recovered
2020-12-15 20:08:00 ERROR (MainThread) [homeassistant.components.upnp] Unexpected error fetching Home Hub 3000 Internet Gateway Device data: Error during async_call(), status: 403, body: <html><body><h1>403 Forbidden</h1></body></html>
Traceback (most recent call last):
  File "/srv/homeassistant/lib/python3.8/site-packages/homeassistant/helpers/update_coordinator.py", line 144, in async_refresh
    self.data = await self._async_update_data()
  File "/srv/homeassistant/lib/python3.8/site-packages/homeassistant/helpers/update_coordinator.py", line 132, in _async_update_data
    return await self.update_method()
  File "/srv/homeassistant/lib/python3.8/site-packages/homeassistant/components/upnp/device.py", line 128, in async_get_traffic_data
    values = await asyncio.gather(
  File "/srv/homeassistant/lib/python3.8/site-packages/async_upnp_client/profiles/igd.py", line 120, in async_get_total_packets_sent
    result = await action.async_call()
  File "/srv/homeassistant/lib/python3.8/site-packages/async_upnp_client/client.py", line 519, in async_call
    raise UpnpError('Error during async_call(), status: %s, body: %s' %
async_upnp_client.client.UpnpError: Error during async_call(), status: 403, body: <html><body><h1>403 Forbidden</h1></body></html>
2020-12-15 20:08:30 INFO (MainThread) [homeassistant.components.upnp] Fetching Home Hub 3000 Internet Gateway Device data recovered
2020-12-15 23:48:30 ERROR (MainThread) [homeassistant.components.upnp] Unexpected error fetching Home Hub 3000 Internet Gateway Device data: Error during async_call(), status: 403, body: <html><body><h1>403 Forbidden</h1></body></html>
Traceback (most recent call last):
  File "/srv/homeassistant/lib/python3.8/site-packages/homeassistant/helpers/update_coordinator.py", line 144, in async_refresh
    self.data = await self._async_update_data()
  File "/srv/homeassistant/lib/python3.8/site-packages/homeassistant/helpers/update_coordinator.py", line 132, in _async_update_data
    return await self.update_method()
  File "/srv/homeassistant/lib/python3.8/site-packages/homeassistant/components/upnp/device.py", line 128, in async_get_traffic_data
    values = await asyncio.gather(
  File "/srv/homeassistant/lib/python3.8/site-packages/async_upnp_client/profiles/igd.py", line 120, in async_get_total_packets_sent
    result = await action.async_call()
  File "/srv/homeassistant/lib/python3.8/site-packages/async_upnp_client/client.py", line 519, in async_call
    raise UpnpError('Error during async_call(), status: %s, body: %s' %
async_upnp_client.client.UpnpError: Error during async_call(), status: 403, body: <html><body><h1>403 Forbidden</h1></body></html>
2020-12-15 23:49:00 INFO (MainThread) [homeassistant.components.upnp] Fetching Home Hub 3000 Internet Gateway Device data recovered
2020-12-16 00:31:30 ERROR (MainThread) [homeassistant.components.upnp] Unexpected error fetching Home Hub 3000 Internet Gateway Device data: Error during async_call(), status: 403, body: <html><body><h1>403 Forbidden</h1></body></html>
Traceback (most recent call last):
  File "/srv/homeassistant/lib/python3.8/site-packages/homeassistant/helpers/update_coordinator.py", line 144, in async_refresh
    self.data = await self._async_update_data()
  File "/srv/homeassistant/lib/python3.8/site-packages/homeassistant/helpers/update_coordinator.py", line 132, in _async_update_data
    return await self.update_method()
  File "/srv/homeassistant/lib/python3.8/site-packages/homeassistant/components/upnp/device.py", line 128, in async_get_traffic_data
    values = await asyncio.gather(
  File "/srv/homeassistant/lib/python3.8/site-packages/async_upnp_client/profiles/igd.py", line 99, in async_get_total_bytes_sent
    result = await action.async_call()
  File "/srv/homeassistant/lib/python3.8/site-packages/async_upnp_client/client.py", line 519, in async_call
    raise UpnpError('Error during async_call(), status: %s, body: %s' %
async_upnp_client.client.UpnpError: Error during async_call(), status: 403, body: <html><body><h1>403 Forbidden</h1></body></html>
2020-12-16 00:32:00 INFO (MainThread) [homeassistant.components.upnp] Fetching Home Hub 3000 Internet Gateway Device data recovered
2020-12-16 00:41:30 ERROR (MainThread) [homeassistant.components.upnp] Unexpected error fetching Home Hub 3000 Internet Gateway Device data: Error during async_call(), status: 403, body: <html><body><h1>403 Forbidden</h1></body></html>
Traceback (most recent call last):
  File "/srv/homeassistant/lib/python3.8/site-packages/homeassistant/helpers/update_coordinator.py", line 144, in async_refresh
    self.data = await self._async_update_data()
  File "/srv/homeassistant/lib/python3.8/site-packages/homeassistant/helpers/update_coordinator.py", line 132, in _async_update_data
    return await self.update_method()
  File "/srv/homeassistant/lib/python3.8/site-packages/homeassistant/components/upnp/device.py", line 128, in async_get_traffic_data
    values = await asyncio.gather(
  File "/srv/homeassistant/lib/python3.8/site-packages/async_upnp_client/profiles/igd.py", line 110, in async_get_total_packets_received
    result = await action.async_call()
  File "/srv/homeassistant/lib/python3.8/site-packages/async_upnp_client/client.py", line 519, in async_call
    raise UpnpError('Error during async_call(), status: %s, body: %s' %
async_upnp_client.client.UpnpError: Error during async_call(), status: 403, body: <html><body><h1>403 Forbidden</h1></body></html>
2020-12-16 00:42:00 INFO (MainThread) [homeassistant.components.upnp] Fetching Home Hub 3000 Internet Gateway Device data recovered
2020-12-16 00:45:30 ERROR (MainThread) [homeassistant.components.upnp] Unexpected error fetching Home Hub 3000 Internet Gateway Device data: Error during async_call(), status: 403, body: <html><body><h1>403 Forbidden</h1></body></html>
Traceback (most recent call last):
  File "/srv/homeassistant/lib/python3.8/site-packages/homeassistant/helpers/update_coordinator.py", line 144, in async_refresh
    self.data = await self._async_update_data()
  File "/srv/homeassistant/lib/python3.8/site-packages/homeassistant/helpers/update_coordinator.py", line 132, in _async_update_data
    return await self.update_method()
  File "/srv/homeassistant/lib/python3.8/site-packages/homeassistant/components/upnp/device.py", line 128, in async_get_traffic_data
    values = await asyncio.gather(
  File "/srv/homeassistant/lib/python3.8/site-packages/async_upnp_client/profiles/igd.py", line 120, in async_get_total_packets_sent
    result = await action.async_call()
  File "/srv/homeassistant/lib/python3.8/site-packages/async_upnp_client/client.py", line 519, in async_call
    raise UpnpError('Error during async_call(), status: %s, body: %s' %
async_upnp_client.client.UpnpError: Error during async_call(), status: 403, body: <html><body><h1>403 Forbidden</h1></body></html>
2020-12-16 00:46:00 INFO (MainThread) [homeassistant.components.upnp] Fetching Home Hub 3000 Internet Gateway Device data recovered
2020-12-16 02:05:06 WARNING (Thread-7) [pychromecast.socket_client] [Kitchen speaker(192.168.1.9):8009] Heartbeat timeout, resetting connection
2020-12-16 02:05:06 INFO (Thread-7) [pychromecast.controllers] Receiver:channel_disconnected
2020-12-16 02:05:23 INFO (Thread-7) [pychromecast.socket_client] [Kitchen speaker(192.168.1.9):8009] Connection reestablished!
2020-12-16 04:09:00 ERROR (MainThread) [homeassistant.components.upnp] Unexpected error fetching Home Hub 3000 Internet Gateway Device data: Error during async_call(), status: 403, body: <html><body><h1>403 Forbidden</h1></body></html>
Traceback (most recent call last):
  File "/srv/homeassistant/lib/python3.8/site-packages/homeassistant/helpers/update_coordinator.py", line 144, in async_refresh
    self.data = await self._async_update_data()
  File "/srv/homeassistant/lib/python3.8/site-packages/homeassistant/helpers/update_coordinator.py", line 132, in _async_update_data
    return await self.update_method()
  File "/srv/homeassistant/lib/python3.8/site-packages/homeassistant/components/upnp/device.py", line 128, in async_get_traffic_data
    values = await asyncio.gather(
  File "/srv/homeassistant/lib/python3.8/site-packages/async_upnp_client/profiles/igd.py", line 110, in async_get_total_packets_received
    result = await action.async_call()
  File "/srv/homeassistant/lib/python3.8/site-packages/async_upnp_client/client.py", line 519, in async_call
    raise UpnpError('Error during async_call(), status: %s, body: %s' %
async_upnp_client.client.UpnpError: Error during async_call(), status: 403, body: <html><body><h1>403 Forbidden</h1></body></html>
2020-12-16 04:09:30 INFO (MainThread) [homeassistant.components.upnp] Fetching Home Hub 3000 Internet Gateway Device data recovered
2020-12-16 04:15:01 WARNING (Thread-7) [pychromecast.socket_client] [Kitchen speaker(192.168.1.9):8009] Heartbeat timeout, resetting connection
2020-12-16 04:15:01 INFO (Thread-7) [pychromecast.controllers] Receiver:channel_disconnected
2020-12-16 04:15:01 WARNING (Thread-6) [pychromecast.socket_client] [Living Room TV(192.168.1.10):8009] Heartbeat timeout, resetting connection
2020-12-16 04:15:01 INFO (Thread-6) [pychromecast.controllers] Receiver:channel_disconnected
2020-12-16 04:15:01 INFO (Thread-7) [pychromecast.socket_client] [Kitchen speaker(192.168.1.9):8009] Connection reestablished!
2020-12-16 04:15:01 INFO (Thread-6) [pychromecast.socket_client] [Living Room TV(192.168.1.10):8009] Connection reestablished!
2020-12-16 04:26:35 WARNING (Thread-6) [pychromecast.socket_client] [Living Room TV(192.168.1.10):8009] Heartbeat timeout, resetting connection
2020-12-16 04:26:35 INFO (Thread-6) [pychromecast.controllers] Receiver:channel_disconnected
2020-12-16 04:27:00 INFO (Thread-6) [pychromecast.socket_client] [Living Room TV(192.168.1.10):8009] Connection reestablished!
2020-12-16 07:22:31 ERROR (MainThread) [homeassistant.components.upnp] Unexpected error fetching Home Hub 3000 Internet Gateway Device data: Error during async_call(), status: 403, body: <html><body><h1>403 Forbidden</h1></body></html>
Traceback (most recent call last):
  File "/srv/homeassistant/lib/python3.8/site-packages/homeassistant/helpers/update_coordinator.py", line 144, in async_refresh
    self.data = await self._async_update_data()
  File "/srv/homeassistant/lib/python3.8/site-packages/homeassistant/helpers/update_coordinator.py", line 132, in _async_update_data
    return await self.update_method()
  File "/srv/homeassistant/lib/python3.8/site-packages/homeassistant/components/upnp/device.py", line 128, in async_get_traffic_data
    values = await asyncio.gather(
  File "/srv/homeassistant/lib/python3.8/site-packages/async_upnp_client/profiles/igd.py", line 120, in async_get_total_packets_sent
    result = await action.async_call()
  File "/srv/homeassistant/lib/python3.8/site-packages/async_upnp_client/client.py", line 519, in async_call
    raise UpnpError('Error during async_call(), status: %s, body: %s' %
async_upnp_client.client.UpnpError: Error during async_call(), status: 403, body: <html><body><h1>403 Forbidden</h1></body></html>
2020-12-16 07:23:01 INFO (MainThread) [homeassistant.components.upnp] Fetching Home Hub 3000 Internet Gateway Device data recovered
2020-12-16 09:53:49 INFO (Thread-6) [pychromecast.socket_client] [Living Room TV(192.168.1.10):8009] Error writing to socket.
2020-12-16 09:53:49 WARNING (Thread-6) [pychromecast.socket_client] [Living Room TV(192.168.1.10):8009] Error communicating with socket, resetting connection
2020-12-16 09:53:49 INFO (Thread-6) [pychromecast.controllers] Receiver:channel_disconnected
2020-12-16 09:53:50 INFO (Thread-6) [pychromecast.socket_client] [Living Room TV(192.168.1.10):8009] Connection reestablished!
2020-12-16 09:56:02 WARNING (MainThread) [homeassistant.helpers.entity] Update of sensor.dark_sky_summary is taking over 10 seconds
2020-12-16 09:59:06 INFO (MainThread) [homeassistant.core] async_stop called twice: ignored
2020-12-16 09:59:06 INFO (MainThread) [homeassistant.core] async_stop called twice: ignored
2020-12-16 09:59:06 INFO (MainThread) [homeassistant.core] async_stop called twice: ignored
2020-12-16 09:59:09 ERROR (MainThread) [root] Uncaught exception
Traceback (most recent call last):
  File "/usr/local/lib/python3.8/asyncio/runners.py", line 43, in run
    return loop.run_until_complete(main)
  File "/usr/local/lib/python3.8/asyncio/base_events.py", line 603, in run_until_complete
    self.run_forever()
  File "/usr/local/lib/python3.8/asyncio/base_events.py", line 570, in run_forever
    self._run_once()
  File "/usr/local/lib/python3.8/asyncio/base_events.py", line 1823, in _run_once
    event_list = self._selector.select(timeout)
  File "/usr/local/lib/python3.8/selectors.py", line 468, in select
    fd_event_list = self._selector.poll(timeout, max_ev)
KeyboardInterrupt

During handling of the above exception, another exception occurred:

Traceback (most recent call last):
  File "/srv/homeassistant/bin/hass", line 8, in <module>
    sys.exit(main())
  File "/srv/homeassistant/lib/python3.8/site-packages/homeassistant/__main__.py", line 312, in main
    exit_code = runner.run(runtime_conf)
  File "/srv/homeassistant/lib/python3.8/site-packages/homeassistant/runner.py", line 133, in run
    return asyncio.run(setup_and_run_hass(runtime_config))
  File "/usr/local/lib/python3.8/asyncio/runners.py", line 50, in run
    loop.close()
  File "/usr/local/lib/python3.8/asyncio/unix_events.py", line 61, in close
    self.remove_signal_handler(sig)
  File "/usr/local/lib/python3.8/asyncio/unix_events.py", line 159, in remove_signal_handler
    signal.set_wakeup_fd(-1)
KeyboardInterrupt
